<?xml version="1.0" ?>

<robot name = "my_rb1_robot">

    <!-- GAZEBO references -->
    <gazebo reference="base_link" >
        <material>Gazebo/Black</material>
    </gazebo>

    <gazebo reference="arrow_link" >
        <material>Gazebo/White</material>
    </gazebo>

    <gazebo reference="elevator_link" >
        <material>Gazebo/Black</material>
    </gazebo>

    <material name="arrow_material">
        <texture filename="package://../img/arrow.png"/>
        
    </material>

    <gazebo reference="joint_chassis_front_caster">
        <preserveFixedJoint>true</preserveFixedJoint>
    </gazebo>
    <gazebo reference="joint_chassis_back_caster">
        <preserveFixedJoint>true</preserveFixedJoint>
    </gazebo>

    <gazebo reference="left_wheel_link">
        <material>Gazebo/Red</material>
        <mu1>1</mu1>
        <mu2>1</mu2>
    </gazebo>
    <gazebo reference="right_wheel_link">
        <material>Gazebo/Red</material>
        <mu1>1</mu1>
        <mu2>1</mu2>
    </gazebo>

    <gazebo reference="back_caster_link">
        <material>Gazebo/White</material>
        <mu1>0.15</mu1>
        <mu2>0.15</mu2>
    </gazebo>

    <gazebo reference="front_caster_link">
        <material>Gazebo/White</material>
        <mu1>0.15</mu1>
        <mu2>0.15</mu2>
    </gazebo>


    <gazebo reference="front_laser">
        <sensor name="lidar" type="ray">
          <always_on>true</always_on>
          <visualize>false</visualize>
          <update_rate>20</update_rate>
          <ray>
              <scan>
                  <horizontal>
                  <samples>720</samples>
                  <resolution>1.000000</resolution>
                  <min_angle>-3.0</min_angle>
                  <max_angle>3.0</max_angle>
                  </horizontal>
              </scan>
              <range>
                  <min>0.120000</min>
                  <max>6.0</max>
                  <resolution>0.015000</resolution>
              </range>
              <noise>
                  <type>gaussian</type>
                  <mean>0.0</mean>
                  <stddev>0.01</stddev>
              </noise>
          </ray>
          <plugin name="scan" filename="libgazebo_ros_ray_sensor.so">
              <ros>
                  <!-- <namespace>${robot_name}</namespace> -->
                  <remapping>~/out:=scan</remapping>
              </ros>
              <output_type>sensor_msgs/LaserScan</output_type>
              <frame_name>front_laser</frame_name>
          </plugin>
          
      </sensor>
    </gazebo>


    <!-- Gazebo diff drive -->
	<gazebo>
		<plugin name='diff_drive' filename='libgazebo_ros_diff_drive.so'>
			<ros>
				<!-- <namespace>/${robot_name}</namespace> -->
				<!-- <argument>cmd_vel:=/cmd_vel</argument> -->
				<!-- <argument>odom:=/odom</argument> -->
			</ros>

			<!-- wheels -->
			<left_joint>joint_base_right_wheel</left_joint>
			<right_joint>joint_base_left_wheel</right_joint>

			<!-- kinematics -->
			<wheel_separation>0.4</wheel_separation>
			<wheel_diameter>0.1</wheel_diameter>

			<!-- limits -->
			<max_wheel_torque>20</max_wheel_torque>
			<max_wheel_acceleration>1.0</max_wheel_acceleration>

			<!-- output -->
			<publish_odom>true</publish_odom>
			<publish_odom_tf>true</publish_odom_tf>
			<publish_wheel_tf>false</publish_wheel_tf>
			

			<odometry_frame>odom</odometry_frame>
			<robot_base_frame>base_footprint</robot_base_frame>
		</plugin>
	</gazebo>
    

    <ros2_control name="GazeboSystem" type="system">
        <hardware>
            <plugin>gazebo_ros2_control/GazeboSystem</plugin>
        </hardware>
        <joint name="elevator_joint">
            <command_interface name="position">
              <param name="min">-100</param>
              <param name="max">100</param>
            </command_interface>
            <state_interface name="position">
              <param name="initial_value">1.0</param>
            </state_interface>
            <state_interface name="velocity"/>
            <state_interface name="effort"/>
        </joint>
    </ros2_control>

    <gazebo>
        <plugin name="gazebo_ros2_control" filename="libgazebo_ros2_control.so">
            <!-- <namespace>rb1</namespace> -->
            <robot_sim_type>gazebo_ros2_control/GazeboSystem</robot_sim_type>
            <robot_param>robot_description</robot_param>
            <robot_param_node>robot_state_publisher</robot_param_node>
            <parameters>$(find rb1_gazebo)/config/elevator_ros2_control.yaml</parameters>
            <!-- <robotSimType>gazebo_ros2_control/DefaultRobotHWSim</robotSimType> -->
        </plugin>
    </gazebo>



    <!-- Link chassis -->
    <link name = "base_link">
        <inertial>
            <mass value = "20" />
            <origin xyz="0 0 0" rpy="0 0 0" />
            <!-- Inertial TODO -->
            <inertia ixx="1.4" ixy="0" ixz="0" iyy="1.4" iyz="0" izz="2.5" />
        </inertial>

        <collision>
            <geometry>
                <cylinder length = "0.30" radius= "0.25" />
            </geometry>
        </collision>

        <visual>
            <geometry>
                <cylinder length = "0.30" radius= "0.25" />
            </geometry>
            <material name = "Blue">
                <color rgba = "0 0 1 0.5" />
            </material>
        </visual>
    </link>

    <link name="elevator_link">
        <inertial>
            <mass value="100"/>
            <inertia ixx="1" ixy="0" ixz="0" iyy="1" iyz="0" izz="1" />
        </inertial>
        <collision>
            <geometry>
                <cylinder length="0.005" radius="0.25"/>
            </geometry>
        </collision>
        <visual>
            <geometry>
                <cylinder length="0.005" radius="0.25"/>
            </geometry>
            <material name = "Black">
                <color rgba = "0 0 0 0" />
            </material>
        </visual>
    </link>

    <joint name="elevator_joint" type="prismatic">
        <parent link="base_link"/>
        <child link="elevator_link"/>
        <origin xyz="0 0 0.16" rpy="0 0 0"/>
        <limit lower="0" upper="2" effort="10000" velocity="0.1"/>
        <axis xyz="0 0 1"/>
    </joint>
    

    <link name = "arrow_link">
        <visual>
            <origin xyz="0 0 0"/>                
            <geometry>
                <box size="0.4 0.1 0.001"/>
            </geometry>
            <material name="White">
                <color rgba="1 1 1 1"/>
            </material>

        </visual>
    </link>

    <joint name="elevator_to_arrow" type="fixed">
        <parent link="elevator_link"/>
        <child link="arrow_link"/>
        <origin xyz="0.0 0.0 0.0025"/>
    </joint>
 
    <link name = "arrow_link_2">
        <visual>
            <origin xyz="0 0 0"/>       <gazebo reference="arrow_link" >
                <material>Gazebo/White</material>
            </gazebo>
                     
            <geometry>
                <box size="0.15 0.1 0.001"/>
            </geometry>
            <material name="White">
                <color rgba="1 1 1 1"/>
            </material>

        </visual>
    </link>

    <joint name="arrow_to_arrow_2" type="fixed">
        <parent link="arrow_link"/>
        <child link="arrow_link_2"/>
        <origin xyz="0.12 -0.07 0.0" rpy="0.0 0.0 0.785"/>
    </joint>

    <link name = "arrow_link_3">
        <visual>
            <origin xyz="0 0 0"/>                
            <geometry>
                <box size="0.15 0.1 0.001"/>
            </geometry>
            <material name="White">
                <color rgba="1 1 1 1"/>
            </material>

        </visual>
    </link>

    <joint name="arrow_to_arrow_3" type="fixed">
        <parent link="arrow_link"/>
        <child link="arrow_link_3"/>
        <origin xyz="0.12 0.07 0.0" rpy="0.0 0.0 -0.785"/>
    </joint>


    <!-- Joints  to left wheel -->
    <joint name = "joint_base_left_wheel" type = "continuous">
        <origin rpy = "-1.57 0 0" xyz = "0.0 -0.2 -0.15" />
        <parent link = "base_link" />
        <child link = "left_wheel_link" />
        <axis rpy = "0 0 0" xyz="0 0 1" />
        <limit effort="10000" velocity="1000" />
        <joint_properties damping = "1.0" friction = "0.75" />
    </joint>

    <!-- Joints  to right wheel -->
    <joint name = "joint_base_right_wheel" type = "continuous">
        <origin rpy = "-1.57 0 0" xyz = "0.0 0.2 -0.15" />
        <parent link = "base_link" />
        <child link = "right_wheel_link" />
        <axis rpy = "0 0 0" xyz="0 0 1" />
        <limit effort="10000" velocity="1000" />
        <joint_properties damping = "1.0" friction = "0.95" />
    </joint>

     <!-- Joints  to caster front wheel -->
    <joint name = "joint_chassis_front_caster" type = "fixed">
        <origin rpy = "0 0 0" xyz = "-0.1 0.0 -0.15" />
        <parent link = "base_link" />
        <child link = "front_caster_link" />
    </joint>

    <!-- Joints  to caster back wheel -->
    <joint name = "joint_chassis_back_caster" type = "fixed">
        <origin rpy = "0 0 0" xyz = "0.1 0.0 -0.15" />
        <parent link = "base_link" />
        <child link = "back_caster_link" />
    </joint>

    <!-- Joints  to base_footprint -->
    <joint name = "joint_chassis_base_footprint" type = "fixed">
        <origin rpy = "0 0 0" xyz = "0.25 0.0 0.095" />
        <parent link = "base_link" />
        <child link = "base_footprint_link" />
    </joint>

    <!-- Joints  to laser -->
    <joint name = "joint_chassis_laser_link" type = "fixed">
        <origin rpy = "3.14 0 0" xyz = "0.25 0.0 0.075" />
        <parent link = "base_link" />
        <child link = "front_laser" />
    </joint>


    <!-- Link left wheel -->
    <link name = "left_wheel_link">
        <inertial>
            <mass value = "1.5" />
            <origin xyz="0 0 0" rpy="0 0 0" />
            <!-- Inertial TODO -->
            <inertia ixx="0.00047" ixy="0" ixz="0" iyy="0.00055" iyz="0" izz="0.00055" />
        </inertial>

        <collision>
            <geometry>
                <cylinder length = "0.05" radius= "0.025" />
            </geometry>
        </collision>

        <visual>
            <geometry>
                <cylinder length = "0.05" radius= "0.025" />
            </geometry>
            <material name = "Red">
                <color rgba = "1 0 0 0.9" />
            </material>
        </visual>
    </link>


    <!-- Link right wheel -->
    <link name = "right_wheel_link">
        <inertial>
            <mass value = "1.5" />
            <origin xyz="0 0 0" rpy="0 0 0" />
            <!-- Inertial TODO -->
            <inertia ixx="0.00047" ixy="0" ixz="0" iyy="0.00055" iyz="0" izz="0.00055" />
        </inertial>

        <collision>
            <geometry>
                <cylinder length = "0.05" radius= "0.025" />
            </geometry>
        </collision>

        <visual>
            <geometry>
                <cylinder length = "0.05" radius= "0.025" />
            </geometry>
            <material name = "Red">
                <color rgba = "1 0 0 0.9" />
            </material>
        </visual>
    </link>


    <!-- Link front caster -->
    <link name = "front_caster_link">
        <inertial>
            <mass value = "1" />
            <origin xyz="0 0 -0.01" rpy="0 0 0" />
            <!-- Inertial TODO -->
            <inertia ixx="0.001" ixy="0" ixz="0" iyy="0.001" iyz="0" izz="0.001" />
        </inertial>

        <collision>
            <geometry>
                <sphere radius = "0.025" />
            </geometry>
        </collision>

        <visual>
            <geometry>
                <sphere radius = "0.025" />
            </geometry>
            <material name = "Blue">
                <color rgba = "1 1 0 0.9" />
            </material>
        </visual>

        <collision>
            <origin xyz="0 0 -0.01" rpy="0 0 0" />
            <geometry>
                <sphere radius = "0.015" />
            </geometry>
        </collision>

        <visual>
            <origin xyz="0 0 -0.01" rpy="0 0 0" />
            <geometry>
                <sphere radius = "0.015" />
            </geometry>
            <material name = "White">
                <color rgba = "1 1 1 0.9" />
            </material>
        </visual>
    </link>


    <!-- Link back caster -->
    <link name = "back_caster_link">
        <inertial>
            <mass value = "1" />
            <origin xyz="0 0 -0.01" rpy="0 0 0" />
            <!-- Inertial TODO -->
            <inertia ixx="0.001" ixy="0" ixz="0" iyy="0.001" iyz="0" izz="0.001" />
        </inertial>

        <collision>
            <geometry>
                <sphere radius = "0.025" />
            </geometry>
        </collision>

        <visual>
            <geometry>
                <sphere radius = "0.025" />
            </geometry>
            <material name = "Blue">
                <color rgba = "1 1 0 0.9" />
            </material>
        </visual>

        <collision>
            <origin xyz="0 0 -0.01" rpy="0 0 0" />
            <geometry>
                <sphere radius = "0.015" />
            </geometry>
        </collision>

        <visual>
            <origin xyz="0 0 -0.01" rpy="0 0 0" />
            <geometry>
                <sphere radius = "0.015" />
            </geometry>
            <material name = "White">
                <color rgba = "1 1 1 0.9" />
            </material>
        </visual>

    </link>


    <link name = "base_footprint_link">
        <inertial>
            <mass value = "0" />
            <origin xyz="0 0 0" rpy="0 0 0" />
            <!-- Inertial TODO -->
            <inertia ixx="0" ixy="0" ixz="0" iyy="0" iyz="0" izz="0" />
        </inertial>
    </link>

    <!-- Kaser link -->
    <link name = "front_laser">
        <inertial>
            <mass value = "0" />
            <origin xyz="0 0 0" rpy="0 0 0" />
            <!-- Inertial TODO -->
            <inertia ixx="0" ixy="0" ixz="0" iyy="0" iyz="0" izz="0" />
        </inertial>
    </link>






</robot>